<?xml version="1.0" ?>
<!-- =================================================================================== -->
<!-- |    This document was autogenerated by xacro from /root/work_place/composite_ws/src/composite_robot/elfin5_scanner_turntable/elfin5_scanner_turntable_description/urdf/elfin5_scanner_turntable.urdf.xacro | -->
<!-- |    EDITING THIS FILE BY HAND IS NOT RECOMMENDED                                 | -->
<!-- =================================================================================== -->
<robot name="elfin5_scanner_turntable">
  <material name="black">
    <color rgba="0.0 0.0 0.0 1.0"/>
  </material>
  <material name="blue">
    <color rgba="0.0 0.0 0.8 1.0"/>
  </material>
  <material name="green">
    <color rgba="0.0 0.8 0.0 1.0"/>
  </material>
  <material name="grey">
    <color rgba="0.2 0.2 0.2 1.0"/>
  </material>
  <material name="orange">
    <color rgba="1.0 0.4235294117647059 0.0392156862745098 1.0"/>
  </material>
  <material name="brown">
    <color rgba="0.8705882352941177 0.8117647058823529 0.7647058823529411 1.0"/>
  </material>
  <material name="red">
    <color rgba="0.8 0.0 0.0 1.0"/>
  </material>
  <material name="white">
    <color rgba="1.0 1.0 1.0 1.0"/>
  </material>
  <material name="metal">
    <color rgba="0.768627450980392 0.749019607843137 0.729411764705882 1"/>
  </material>
  <material name="metal_grey">
    <color rgba="0.501960784313725 0.501960784313725 0.501960784313725 1"/>
  </material>
  <material name="metal_white">
    <color rgba="0.866666666666667 0.866666666666667 0.890196078431373 1"/>
  </material>
  <!-- ros_control plugin -->
  <gazebo>
    <plugin filename="libgazebo_ros_control.so" name="gazebo_ros_control">
      <robotSimType>gazebo_ros_control/DefaultRobotHWSim</robotSimType>
      <legacyModeNS>true</legacyModeNS>
    </plugin>
  </gazebo>
  <gazebo reference="elfin_link2">
    <visual name="visual">
      <material>
        <script>
          <uri>file://media/materials/scripts/gazebo.material</uri>
          <name>Gazebo/Grey</name>
        </script>
      </material>
    </visual>
  </gazebo>
  <gazebo reference="elfin_link4">
    <visual name="visual">
      <material>
        <script>
          <uri>file://media/materials/scripts/gazebo.material</uri>
          <name>Gazebo/Grey</name>
        </script>
      </material>
    </visual>
  </gazebo>
  <transmission name="elfin_joint1_trans">
    <type>transmission_interface/SimpleTransmission</type>
    <joint name="elfin_joint1">
      <hardwareInterface>hardware_interface/PositionJointInterface</hardwareInterface>
    </joint>
    <actuator name="elfin_joint1_motor">
      <mechanicalReduction>1</mechanicalReduction>
    </actuator>
  </transmission>
  <transmission name="elfin_joint2_trans">
    <type>transmission_interface/SimpleTransmission</type>
    <joint name="elfin_joint2">
      <hardwareInterface>hardware_interface/PositionJointInterface</hardwareInterface>
    </joint>
    <actuator name="elfin_joint2_motor">
      <mechanicalReduction>1</mechanicalReduction>
    </actuator>
  </transmission>
  <transmission name="elfin_joint3_trans">
    <type>transmission_interface/SimpleTransmission</type>
    <joint name="elfin_joint3">
      <hardwareInterface>hardware_interface/PositionJointInterface</hardwareInterface>
    </joint>
    <actuator name="elfin_joint3_motor">
      <mechanicalReduction>1</mechanicalReduction>
    </actuator>
  </transmission>
  <transmission name="elfin_joint4_trans">
    <type>transmission_interface/SimpleTransmission</type>
    <joint name="elfin_joint4">
      <hardwareInterface>hardware_interface/PositionJointInterface</hardwareInterface>
    </joint>
    <actuator name="elfin_joint4_motor">
      <mechanicalReduction>1</mechanicalReduction>
    </actuator>
  </transmission>
  <transmission name="elfin_joint5_trans">
    <type>transmission_interface/SimpleTransmission</type>
    <joint name="elfin_joint5">
      <hardwareInterface>hardware_interface/PositionJointInterface</hardwareInterface>
    </joint>
    <actuator name="elfin_joint5_motor">
      <mechanicalReduction>1</mechanicalReduction>
    </actuator>
  </transmission>
  <transmission name="elfin_joint6_trans">
    <type>transmission_interface/SimpleTransmission</type>
    <joint name="elfin_joint6">
      <hardwareInterface>hardware_interface/PositionJointInterface</hardwareInterface>
    </joint>
    <actuator name="elfin_joint6_motor">
      <mechanicalReduction>1</mechanicalReduction>
    </actuator>
  </transmission>
  <!-- world -->
  <link name="world"/>
  <transmission name="turntable_trans">
    <type>transmission_interface/SimpleTransmission</type>
    <joint name="turntable_support_joint">
      <hardwareInterface>hardware_interface/PositionJointInterface</hardwareInterface>
    </joint>
    <actuator name="turntable_motor">
      <mechanicalReduction>1</mechanicalReduction>
      <hardwareInterface>hardware_interface/PositionJointInterface</hardwareInterface>
    </actuator>
  </transmission>
  <joint name="turntable_base_joint" type="fixed">
    <parent link="world"/>
    <child link="turntable_base_link"/>
    <origin rpy="0 0 0" xyz="0.95 0 -0.01"/>
  </joint>
  <link name="turntable_base_link">
    <inertial>
      <origin rpy="0 0 0" xyz="0.025941 0.017099 0.020883"/>
      <mass value="0.47747"/>
      <inertia ixx="0.00034258" ixy="7.1646E-06" ixz="2.4443E-06" iyy="0.00032297" iyz="5.1465E-06" izz="0.00058903"/>
    </inertial>
    <visual>
      <origin rpy="0 0 0" xyz="0 0 0"/>
      <geometry>
        <mesh filename="package://turntable_description/meshes/turntable_base_link.STL"/>
      </geometry>
      <material name="">
        <color rgba="0.75294 0.75294 0.75294 1"/>
      </material>
    </visual>
    <collision>
      <origin rpy="0 0 0" xyz="0 0 0"/>
      <geometry>
        <mesh filename="package://turntable_description/meshes/turntable_base_link.STL"/>
      </geometry>
    </collision>
  </link>
  <link name="turntable_support_link">
    <inertial>
      <origin rpy="0 0 0" xyz="0 -2.0817E-17 -0.002003"/>
      <mass value="0.28146"/>
      <inertia ixx="0.0015904" ixy="1.3056E-22" ixz="5.1773E-24" iyy="0.0015904" iyz="5.1068E-23" izz="0.00318"/>
    </inertial>
    <visual>
      <origin rpy="0 0 0" xyz="0 0 0"/>
      <geometry>
        <mesh filename="package://turntable_description/meshes/turntable_support_link.STL"/>
      </geometry>
      <material name="">
        <color rgba="1 1 1 1"/>
      </material>
    </visual>
    <collision>
      <origin rpy="0 0 0" xyz="0 0 0"/>
      <geometry>
        <mesh filename="package://turntable_description/meshes/turntable_support_link.STL"/>
      </geometry>
    </collision>
  </link>
  <joint name="turntable_support_joint" type="revolute">
    <origin rpy="0 0 0" xyz="0 0 0.049"/>
    <parent link="turntable_base_link"/>
    <child link="turntable_support_link"/>
    <axis xyz="0 0 1"/>
    <limit effort="10" lower="-3.1415926" upper="3.1415926" velocity="10"/>
  </joint>
  <joint name="elfin_base_link_joint" type="fixed">
    <parent link="world"/>
    <child link="elfin_base_link"/>
    <origin rpy="0 0 0" xyz="0 0 0"/>
  </joint>
  <link name="elfin_base_link"/>
  <joint name="elfin_base_joint" type="fixed">
    <origin rpy="0 0 1.5707963267948966" xyz="0 0 0"/>
    <parent link="elfin_base_link"/>
    <child link="elfin_base"/>
  </joint>
  <link name="elfin_base">
    <inertial>
      <origin rpy="0 0 0" xyz="0.00022102 0.0013404 0.025529"/>
      <mass value="2.13370989"/>
      <inertia ixx="0.0040358799" ixy="0.00017551199999999998" ixz="5.840099999999999e-06" iyy="0.0041550303" iyz="3.38355e-05" izz="0.007080395099999999"/>
    </inertial>
    <visual>
      <origin rpy="0 0 0" xyz="0 0 0"/>
      <geometry>
        <mesh filename="package://elfin_description/meshes/elfin5/elfin_base.STL"/>
      </geometry>
      <material name="metal_white"/>
    </visual>
    <collision>
      <origin rpy="0 0 0" xyz="0 0 0"/>
      <geometry>
        <mesh filename="package://elfin_description/meshes/elfin5/elfin_base.STL"/>
      </geometry>
    </collision>
  </link>
  <link name="elfin_link1">
    <inertial>
      <origin rpy="0 0 0" xyz="-0.021815 -1.1609E-05 0.095394"/>
      <mass value="7.96222548"/>
      <inertia ixx="0.0401380494" ixy="0.0088981494" ixz="-3.0899999999999996e-06" iyy="0.0222824535" iyz="-1.6068e-06" izz="0.047360831699999995"/>
    </inertial>
    <visual>
      <origin rpy="0 0 0" xyz="0 0 0"/>
      <geometry>
        <mesh filename="package://elfin_description/meshes/elfin5/elfin_link1.STL"/>
      </geometry>
      <material name="metal"/>
    </visual>
    <collision>
      <origin rpy="0 0 0" xyz="0 0 0"/>
      <geometry>
        <mesh filename="package://elfin_description/meshes/elfin5/elfin_link1.STL"/>
      </geometry>
    </collision>
  </link>
  <joint name="elfin_joint1" type="revolute">
    <origin rpy="0 0 0" xyz="0 0 0.0735"/>
    <parent link="elfin_base"/>
    <child link="elfin_link1"/>
    <axis xyz="0 0 1"/>
    <limit effort="200" lower="-3.14" upper="3.14" velocity="1.57"/>
  </joint>
  <link name="elfin_link2">
    <inertial>
      <origin rpy="0 0 0" xyz="-0.15508 0.031021 0.052499"/>
      <mass value="3.73459563"/>
      <inertia ixx="0.091957473" ixy="-0.0039070269" ixz="-7.415999999999999e-07" iyy="0.005196020399999999" iyz="-6.488999999999999e-06" izz="0.0909910446"/>
    </inertial>
    <visual>
      <origin rpy="0 0 0" xyz="0 0 0"/>
      <geometry>
        <mesh filename="package://elfin_description/meshes/elfin5/elfin_link2.STL"/>
      </geometry>
      <material name="metal_grey"/>
    </visual>
    <collision>
      <origin rpy="0 0 0" xyz="0 0 0"/>
      <geometry>
        <mesh filename="package://elfin_description/meshes/elfin5/elfin_link2.STL"/>
      </geometry>
    </collision>
  </link>
  <joint name="elfin_joint2" type="revolute">
    <origin rpy="1.5708 1.3734 -1.5708" xyz="-0.078 0 0.1465"/>
    <parent link="elfin_link1"/>
    <child link="elfin_link2"/>
    <axis xyz="0 0 1"/>
    <limit effort="200" lower="-2.35" upper="2.35" velocity="1.57"/>
  </joint>
  <link name="elfin_link3">
    <inertial>
      <origin rpy="0 0 0" xyz="1.1184E-05 0.041481 -0.052586"/>
      <mass value="4.71497847"/>
      <inertia ixx="0.0163101015" ixy="0.003836235" ixz="-5.562e-07" iyy="0.0098219049" iyz="-2.0703e-06" izz="0.0201630843"/>
    </inertial>
    <visual>
      <origin rpy="0 0 0" xyz="0 0 0"/>
      <geometry>
        <mesh filename="package://elfin_description/meshes/elfin5/elfin_link3.STL"/>
      </geometry>
      <material name="metal"/>
    </visual>
    <collision>
      <origin rpy="0 0 0" xyz="0 0 0"/>
      <geometry>
        <mesh filename="package://elfin_description/meshes/elfin5/elfin_link3.STL"/>
      </geometry>
    </collision>
  </link>
  <joint name="elfin_joint3" type="revolute">
    <origin rpy="0 0 1.3734" xyz="-0.37262 0.074541 -0.0060028"/>
    <parent link="elfin_link2"/>
    <child link="elfin_link3"/>
    <axis xyz="0 0 -1"/>
    <limit effort="200" lower="-2.61" upper="2.61" velocity="1.57"/>
  </joint>
  <link name="elfin_link4">
    <inertial>
      <origin rpy="0 0 0" xyz="-0.058961 3.7945E-05 0.13807"/>
      <mass value="1.46783034"/>
      <inertia ixx="0.0167614269" ixy="0.004792342799999999" ixz="-1.6377e-06" iyy="0.004072002" iyz="6.025499999999999e-06" izz="0.0187714101"/>
    </inertial>
    <visual>
      <origin rpy="0 0 0" xyz="0 0 0"/>
      <geometry>
        <mesh filename="package://elfin_description/meshes/elfin5/elfin_link4.STL"/>
      </geometry>
      <material name="metal_grey"/>
    </visual>
    <collision>
      <origin rpy="0 0 0" xyz="0 0 0"/>
      <geometry>
        <mesh filename="package://elfin_description/meshes/elfin5/elfin_link4.STL"/>
      </geometry>
    </collision>
  </link>
  <joint name="elfin_joint4" type="revolute">
    <origin rpy="0 1.5708 1.5708" xyz="0 0.119 -0.072"/>
    <parent link="elfin_link3"/>
    <child link="elfin_link4"/>
    <axis xyz="0 0 1"/>
    <limit effort="104" lower="-3.14" upper="3.14" velocity="1.57"/>
  </joint>
  <link name="elfin_link5">
    <inertial>
      <origin rpy="0 0 0" xyz="3.4043E-06 -0.036593 -0.044531"/>
      <mass value="2.49795291"/>
      <inertia ixx="0.0060069291" ixy="0.0014650925999999999" ixz="3.09e-08" iyy="0.0034992704999999994" iyz="-3.7079999999999996e-07" izz="0.0076218249"/>
    </inertial>
    <visual>
      <origin rpy="0 0 0" xyz="0 0 0"/>
      <geometry>
        <mesh filename="package://elfin_description/meshes/elfin5/elfin_link5.STL"/>
      </geometry>
      <material name="metal"/>
    </visual>
    <collision>
      <origin rpy="0 0 0" xyz="0 0 0"/>
      <geometry>
        <mesh filename="package://elfin_description/meshes/elfin5/elfin_link5.STL"/>
      </geometry>
    </collision>
  </link>
  <joint name="elfin_joint5" type="revolute">
    <origin rpy="-1.5708 0 1.5708" xyz="-0.0605 0 0.301"/>
    <parent link="elfin_link4"/>
    <child link="elfin_link5"/>
    <axis xyz="0 0 -1"/>
    <limit effort="34" lower="-2.56" upper="2.56" velocity="1.57"/>
  </joint>
  <link name="elfin_link6">
    <inertial>
      <origin rpy="0 0 0" xyz="-0.007255 -3.2028E-05 0.033062"/>
      <mass value="0.45519408"/>
      <inertia ixx="0.0005996762999999999" ixy="4.326e-06" ixz="-8.9301e-06" iyy="0.0006053928" iyz="1.545e-07" izz="0.0006024263999999999"/>
    </inertial>
    <visual>
      <origin rpy="0 0 0" xyz="0 0 0"/>
      <geometry>
        <mesh filename="package://elfin_description/meshes/elfin5/elfin_link6.STL"/>
      </geometry>
      <material name="metal_white"/>
    </visual>
    <collision>
      <origin rpy="0 0 0" xyz="0 0 0"/>
      <geometry>
        <mesh filename="package://elfin_description/meshes/elfin5/elfin_link6.STL"/>
      </geometry>
    </collision>
  </link>
  <joint name="elfin_joint6" type="revolute">
    <origin rpy="1.5708 1.5708 0" xyz="0 -0.1005 -0.0605"/>
    <parent link="elfin_link5"/>
    <child link="elfin_link6"/>
    <axis xyz="0 0 1"/>
    <limit effort="34" lower="-3.14" upper="3.14" velocity="1.57"/>
  </joint>
  <link name="elfin_end_link"/>
  <joint name="elfin_end_joint" type="fixed">
    <origin rpy="0 0 -1.5708" xyz="0 0 0.0545"/>
    <parent link="elfin_link6"/>
    <child link="elfin_end_link"/>
  </joint>
  <link name="elfin_dummy_gripper"/>
  <joint name="elfin_dummy_joint" type="fixed">
    <origin rpy="1.5707963267948966 1.5707963267948966 0" xyz="0 -0.0935 0"/>
    <parent link="elfin_link6"/>
    <child link="elfin_dummy_gripper"/>
  </joint>
  <link name="dummy_gripper"/>
  <joint name="dummy_joint" type="fixed">
    <!-- 手爪末端 虚拟关节 -->
    <origin rpy="0 0 0" xyz="0 0 0"/>
    <parent link="elfin_end_link"/>
    <child link="dummy_gripper"/>
  </joint>
  <!-- 连接 camera_orin 的 parent frame  -->
  <joint name="gw_scanner_mount_joint" type="fixed">
    <parent link="elfin_end_link"/>
    <child link="gw_scanner_mount_base_link"/>
    <origin rpy="0 0 -1.9634954087948966" xyz="0 0 -0.006"/>
  </joint>
  <link name="gw_scanner_mount_base_link">
    <inertial>
      <origin rpy="0 0 0" xyz="0 -0.015735 0.0056215"/>
      <mass value="0.074594"/>
      <inertia ixx="6.3454E-05" ixy="3.2515E-21" ixz="-5.5646E-22" iyy="4.7313E-05" iyz="4.4432E-07" izz="0.00010901"/>
    </inertial>
    <visual>
      <origin rpy="0 0 0" xyz="0 0 0"/>
      <geometry>
        <mesh filename="package://gw_scanner_mount_description/meshes/gw_scanner_mount_base_link.STL"/>
      </geometry>
      <material name="">
        <color rgba="0.79216 0.81961 0.93333 1"/>
      </material>
    </visual>
    <collision>
      <origin rpy="0 0 0" xyz="0 0 0"/>
      <geometry>
        <mesh filename="package://gw_scanner_mount_description/meshes/gw_scanner_mount_base_link.STL"/>
      </geometry>
    </collision>
  </link>
  <link name="gw_scanner_support_link">
    <inertial>
      <origin rpy="0 0 0" xyz="1.7347E-17 0.0025 0.00032874"/>
      <mass value="0.043909"/>
      <inertia ixx="1.7367E-05" ixy="-3.8689E-22" ixz="-1.2948E-21" iyy="7.7353E-05" iyz="-3.1669E-24" izz="6.0169E-05"/>
    </inertial>
    <visual>
      <origin rpy="0 0 0" xyz="0 0 0"/>
      <geometry>
        <mesh filename="package://gw_scanner_mount_description/meshes/gw_scanner_support_link.STL"/>
      </geometry>
      <material name="">
        <color rgba="1 1 1 1"/>
      </material>
    </visual>
    <collision>
      <origin rpy="0 0 0" xyz="0 0 0"/>
      <geometry>
        <mesh filename="package://gw_scanner_mount_description/meshes/gw_scanner_support_link.STL"/>
      </geometry>
    </collision>
  </link>
  <joint name="gw_scanner_support_joint" type="fixed">
    <origin rpy="0 0 0" xyz="0 -0.065 0.035"/>
    <parent link="gw_scanner_mount_base_link"/>
    <child link="gw_scanner_support_link"/>
    <axis xyz="0 0 0"/>
  </joint>
  <link name="gripper_support_link"/>
  <joint name="gripper_support_joint" type="fixed">
    <origin rpy="0 0 0" xyz="0 0 0.012"/>
    <parent link="gw_scanner_mount_base_link"/>
    <child link="gripper_support_link"/>
    <axis xyz="0 0 1"/>
  </joint>
  <link name="kinect_image_frame"/>
  <joint name="kinect_image_frame_joint" type="fixed">
    <origin rpy="1.57 -1.57 0" xyz="0 0 0"/>
    <parent link="gw_scanner_depth_frame"/>
    <child link="kinect_image_frame"/>
  </joint>
  <gazebo reference="kinect_image_frame">
    <sensor name="gw_scanner" type="depth">
      <always_on>true</always_on>
      <update_rate>20.0</update_rate>
      <camera>
        <horizontal_fov>1.0471975333333332</horizontal_fov>
        <image>
          <format>R8G8B8</format>
          <width>640</width>
          <height>480</height>
        </image>
        <clip>
          <near>0.05</near>
          <far>8.0</far>
        </clip>
      </camera>
      <plugin filename="libgazebo_ros_openni_kinect.so" name="kinect_camera_controller">
        <cameraName>camera</cameraName>
        <alwaysOn>true</alwaysOn>
        <updateRate>10</updateRate>
        <imageTopicName>rgb/image_raw</imageTopicName>
        <depthImageTopicName>depth/image_raw</depthImageTopicName>
        <pointCloudTopicName>depth/points</pointCloudTopicName>
        <cameraInfoTopicName>rgb/camera_info</cameraInfoTopicName>
        <depthImageCameraInfoTopicName>depth/camera_info</depthImageCameraInfoTopicName>
        <frameName>gw_scanner_depth_frame</frameName>
        <baseline>0.1</baseline>
        <distortion_k1>0.0</distortion_k1>
        <distortion_k2>0.0</distortion_k2>
        <distortion_k3>0.0</distortion_k3>
        <distortion_t1>0.0</distortion_t1>
        <distortion_t2>0.0</distortion_t2>
        <pointCloudCutoff>0.4</pointCloudCutoff>
      </plugin>
    </sensor>
  </gazebo>
  <!-- 连接 camera_orin 的 parent frame  -->
  <joint name="gw_scanner_joint" type="fixed">
    <parent link="gw_scanner_support_link"/>
    <child link="gw_scanner_base_link"/>
    <origin rpy="0 0 0" xyz="0 0 0"/>
  </joint>
  <link name="gw_scanner_base_link">
    <inertial>
      <origin rpy="0 0 0" xyz="0.00048902 -0.038928 -0.00015865"/>
      <mass value="2.6858"/>
      <inertia ixx="0.0046973" ixy="-2.4329E-06" ixz="6.548E-06" iyy="0.016988" iyz="-4.7832E-05" izz="0.014204"/>
    </inertial>
    <visual>
      <origin rpy="0 0 0" xyz="0 0 0"/>
      <geometry>
        <mesh filename="package://gw_scanner_description/meshes/gw_scanner_base_link.STL"/>
      </geometry>
      <material name="">
        <color rgba="0.75294 0.75294 0.75294 1"/>
      </material>
    </visual>
    <collision>
      <origin rpy="0 0 0" xyz="0 0 0"/>
      <geometry>
        <mesh filename="package://gw_scanner_description/meshes/gw_scanner_base_link.STL"/>
      </geometry>
    </collision>
  </link>
  <link name="gw_scanner_depth_frame"/>
  <joint name="gw_scanner_depth_joint" type="fixed">
    <origin rpy="0 0 0.088" xyz="-0.085 -0.04 0.05"/>
    <parent link="gw_scanner_base_link"/>
    <child link="gw_scanner_depth_frame"/>
  </joint>
</robot>

