<?xml version="1.0" ?>
<!-- =================================================================================== -->
<!-- |    This document was autogenerated by xacro from /root/work_place/composite_ws/src/turntable/turntable_description/urdf/turntable_standalone.xacro | -->
<!-- |    EDITING THIS FILE BY HAND IS NOT RECOMMENDED                                 | -->
<!-- =================================================================================== -->
<robot name="turntable">
    <link name="map" />
    <transmission name="turntable_trans">
        <type>transmission_interface/SimpleTransmission</type>
        <joint name="turntable_support_joint">
            <hardwareInterface>hardware_interface/PositionJointInterface</hardwareInterface>
        </joint>
        <actuator name="turntable_motor">
            <mechanicalReduction>1</mechanicalReduction>
            <hardwareInterface>hardware_interface/PositionJointInterface</hardwareInterface>
        </actuator>
    </transmission>
    <joint name="turntable_base_joint" type="fixed">
        <parent link="map" />
        <child link="turntable_base_link" />
        <origin rpy="0 0 0" xyz="0 0 0" />
    </joint>
    <link name="turntable_base_link">
        <inertial>
            <origin rpy="0 0 0" xyz="0.025941 0.017099 0.020883" />
            <mass value="0.47747" />
            <inertia ixx="0.00034258" ixy="7.1646E-06" ixz="2.4443E-06" iyy="0.00032297" iyz="5.1465E-06" izz="0.00058903" />
        </inertial>
        <visual>
            <origin rpy="0 0 0" xyz="0 0 0" />
            <geometry>
                <mesh filename="package://turntable_description/meshes/turntable_base_link.STL" />
            </geometry>
            <material name="">
                <color rgba="0.75294 0.75294 0.75294 1" />
            </material>
        </visual>
        <collision>
            <origin rpy="0 0 0" xyz="0 0 0" />
            <geometry>
                <mesh filename="package://turntable_description/meshes/turntable_base_link.STL" />
            </geometry>
        </collision>
    </link>
    <link name="turntable_support_link">
        <inertial>
            <origin rpy="0 0 0" xyz="0 -2.0817E-17 -0.002003" />
            <mass value="0.28146" />
            <inertia ixx="0.0015904" ixy="1.3056E-22" ixz="5.1773E-24" iyy="0.0015904" iyz="5.1068E-23" izz="0.00318" />
        </inertial>
        <visual>
            <origin rpy="0 0 0" xyz="0 0 0" />
            <geometry>
                <mesh filename="package://turntable_description/meshes/turntable_support_link.STL" />
            </geometry>
            <material name="">
                <color rgba="1 1 1 1" />
            </material>
        </visual>
        <collision>
            <origin rpy="0 0 0" xyz="0 0 0" />
            <geometry>
                <mesh filename="package://turntable_description/meshes/turntable_support_link.STL" />
            </geometry>
        </collision>
    </link>
    <joint name="turntable_support_joint" type="revolute">
        <origin rpy="0 0 0" xyz="0 0 0.049" />
        <parent link="turntable_base_link" />
        <child link="turntable_support_link" />
        <axis xyz="0 0 1" />
        <limit effort="10" lower="-3.1415926" upper="3.1415926" velocity="10" />
    </joint>
    <!-- <gazebo>
        <plugin name="gazebo_ros_control">
            <robotNamespace>/</robotNamespace>
        </plugin>
    </gazebo> -->
</robot>
